Workbook

Sheet Accueil
B1: Saint-Tableur pour option Physique/Méca, 2022-2024 | D1: Résumé des notes
B3: Les différents semestres sont accessibles par les onglets en bas | D3: Semestre 1 | E3: ='Semestre 1'!I34 -> 0 | G3: Semestre 3 | H3: ='Semestre 3'!J31 -> 0
B4: Ce tableur prend en compte les notes bonus et les notes encore inconnues | E4: ='Semestre 1'!H35 -> - - - | H4: ='Semestre 3'!H32 -> - - -
B5: Pour chaque semestre, vous pourrez voir vos moyennes par matières et la validation potentiel
D6: Semestre 2 | E6: ='Semestre 2'!I41 -> 0 | G6: Semestre 4 | H6: ='Semestre 4'!J34 -> 0
B7: Les cases blanches contiennent des formules, ne les modifiez pas | E7: ='Semestre 2'!H42 -> - - - | H7: ='Semestre 4'!H35 -> - - -
B9: Les cases grises sont là où vous pouvez rentrer vos notes
D10: Année 1 | E10: =IF(E3+E6=0,0,((E3+E6)/(IF(E3=0,0,1)+IF(E6=0,0,1)))) -> 0 | G10: Année 2 | H10: =IF(H3+H6=0,0,((H3+H6)/(IF(H3=0,0,1)+IF(H6=0,0,1)))) -> 0
B11: Les cases vertes indiquent une note bonus | E11: =IF(AND('Semestre 1'!I32=0,'Semestre 2'!I39=0),"- - -",IF(AND(('Semestre 1'!I32+'Semestre 2'!I39)/(IF('Semestre 1'!I32=0,0,1)+IF('Semestre 2'!I39=0,0,1))>=10,NOT('Semestre 1'!I33="NVAL"),NOT('Semestre 2'!I40="NVAL")),"Année validée","Année échouée")) -> - - - | H11: =IF(AND('Semestre 3'!J29=0,'Semestre 4'!J32=0),"- - -",IF(AND(('Semestre 3'!J29+'Semestre 4'!J32)/(IF('Semestre 3'!J29=0,0,1)+IF('Semestre 4'!J32=0,0,1))>=10,NOT('Semestre 3'!J30="NVAL"),NOT('Semestre 4'!J33="NVAL")),"Année validée","Année échouée")) -> - - -
B13: Le Saint-Tableur originel est de Dorian (https://dorian-tonnis.fr/)
B14: Cette version est de moi (julien) | D14: PeiP | E14: =IF(E10+H10=0,0,((E10+H10)/(IF(E10=0,0,1)+IF(H10=0,0,1)))) -> 0
E15: =IF(E14=0,"- - -",IF(AND(NOT(E11="Année échouée"),NOT(H11="Année échouée")),"PeiP validé","PeiP échoué")) -> - - -

Sheet Semestre 1
A1: UE | C1: Crédits | D1: Evaluations | F1: Notes | H1: Coefficients | I1: Moyenne
A2: Maths | C2: 12 | D2: Khôlles | E2: 1 | G2: =IF(COUNT(F2:F6)=1,AVERAGE(F2:F6),(SUM(F2:F6)-MIN(F2:F6))/(COUNT(F2:F6)-1)) -> 0 | H2: 0.4 | I2: =IF(SUM(F2:G12)=0,0,(G2*H2+G7*H7+G11*H11)/(IF(G2=0,0,H2)+IF(G7=0,0,H7)+IF(G11=0,0,H11))) -> 0
E3: 2
E4: 3
E5: 4
E6: 5
D7: DS | E7: 1 | G7: =IF(COUNT(F7:F10)=1,AVERAGE(F7:F10),(SUM(F7:F10)-MIN(F7:F10))/(COUNT(F7:F10)-1)) -> 0 | H7: 0.3
E8: 2
E9: 3
E10: 4
A11: Algèbre | D11: Examen | G11: =IF(COUNT(F11:F12)=0,0,AVERAGE(F11:F12)) -> 0 | H11: 0.3 | I11: =IF(SUM(F2:G10)+F11=0,0,(G2*H2+G7*H7+F11*H11)/(IF(G2=0,0,H2)+IF(G7=0,0,H7)+IF(F11=0,0,H11))) -> 0
A12: Analyse | I12: =IF(SUM(F2:G10)+F12=0,0,(G2*H2+G7*H7+F12*H11)/(IF(G2=0,0,H2)+IF(G7=0,0,H7)+IF(F12=0,0,H11))) -> 0
A13: Physique-chimie | B13: Physique | C13: 6 | D13: Khôlle | H13: 0.1 | I13: =IF(SUM(F13:G16)=0,0,(F13*H13+F14*H14+F15*H15+F16*H16)/(IF(F13=0,0,H13)+IF(F14=0,0,H14)+IF(F15=0,0,H15)+IF(F16=0,0,H16))) -> 0 | J13: =IF(SUM(F13:G20)=0,0,(I13+I17)/(IF(I13=0,0,1)+IF(I17=0,0,1))) -> 0
D14: DS | E14: 1 | H14: 0.2
E15: 2 | H15: 0.3
D16: Examen | H16: 0.4
B17: Chimie | D17: Khôlle | H17: 0.1 | I17: =IF(SUM(F17:G20)=0,0,(F17*H17+F18*H18+F19*H19+F20*H20)/(IF(F17=0,0,H17)+IF(F18=0,0,H18)+IF(F19=0,0,H19)+IF(F20=0,0,H20))) -> 0
D18: DS | E18: 1 | H18: 0.2
E19: 2 | H19: 0.3
D20: Examen | H20: 0.4
A21: Info | C21: 6 | D21: Asker | H21: 0.06 | I21: =IF(SUM(F21:G26)=0,0,(F21*H21+F22*H22+F23*H23+F24*H24+G25*H25)/(IF(F21=0,0,H21)+IF(F22=0,0,H22)+IF(F23=0,0,H23)+IF(F24=0,0,H24)+IF(G25=0,0,H25))) -> 0
D22: TP noté | E22: 1 | H22: 0.14
E23: 2 | H23: 0.2
D24: DS | H24: 0.2
D25: Examen | E25: Algo | G25: =IF(COUNT(F25:F26)=0,0,AVERAGE(F25:F26)) -> 0 | H25: 0.4
E26: C++
A27: Transversales | B27: Anglais | C27: 2 | D27: Moyenne | H27: 1 | I27: =F27 -> 0 | J27: =IF(SUM(F27:G29)=0,0,(I27+I28)/(IF(I27=0,0,1)+IF(I28=0,0,1))) -> 0
B28: Français | D28: Module | E28: 1 | H28: 1 | I28: =IF(SUM(F28:G29)=0,0,AVERAGE(F28:G29)) -> 0
E29: 2
B30: Pix | C30: 3 | D30: Moyenne | H30: 1 | I30: =F30 -> 0
B31: Sport | C31: 1 | D31: Moyenne | H31: 1 | I31: =F31 -> 0
H32: SCIENCES | I32: =IF(SUM(I2:J26)=0,0,(I2*C2+J13*C13+I21*C21)/(IF(I2=0,0,C2)+IF(J13=0,0,C13)+IF(I21=0,0,C21))) -> 0
H33: TR | I33: =IF(SUM(I27:J31)=0,"- - -",IF(AND(OR(J27=0,J27>=10),OR(I30=0,I30>=10),OR(I31=0,I31>=10)),"VAL","NVAL")) -> - - -
H34: TOTAL | I34: =IF(SUM(I2:J31)=0,0,(I2*C2+J13*C13+I21*C21+J27*C27+I30*C30+I31*C31)/(IF(I2=0,0,C2)+IF(J13=0,0,C13)+IF(I21=0,0,C21)+IF(J27=0,0,C27)+IF(I30=0,0,C30)+IF(I31=0,0,C31))) -> 0
H35: =IF(I32=0,"- - -",IF(AND(I32>=10,NOT(I33="NVAL")),"Semestre validé","Semestre échoué")) -> - - -

Sheet Semestre 2
A1: UE | C1: Crédits | D1: Evaluations | F1: Notes | H1: Coefficients | I1: Moyenne
A2: Maths | C2: 12 | D2: Khôlles | E2: 1 | G2: =IF(COUNT(F2:F6)=1,AVERAGE(F2:F6),(SUM(F2:F6)-MIN(F2:F6))/(COUNT(F2:F6)-1)) -> 0 | H2: 0.4 | I2: =IF(SUM(F2:G12)=0,0,(G2*H2+G7*H7+G11*H11)/(IF(G2=0,0,H2)+IF(G7=0,0,H7)+IF(G11=0,0,H11))) -> 0
E3: 2
E4: 3
E5: 4
E6: 5
D7: DS | E7: 1 | G7: =IF(COUNT(F7:F10)=1,AVERAGE(F7:F10),(SUM(F7:F10)-MIN(F7:F10))/(COUNT(F7:F10)-1)) -> 0 | H7: 0.3
E8: 2
E9: 3
E10: 4
A11: Algèbre | D11: Examen | G11: =IF(COUNT(F11:F12)=0,0,AVERAGE(F11:F12)) -> 0 | H11: 0.3 | I11: =IF(SUM(F2:G10)+F11=0,0,(G2*H2+G7*H7+F11*H11)/(IF(G2=0,0,H2)+IF(G7=0,0,H7)+IF(F11=0,0,H11))) -> 0
A12: Analyse | I12: =IF(SUM(F2:G10)+F12=0,0,(G2*H2+G7*H7+F12*H11)/(IF(G2=0,0,H2)+IF(G7=0,0,H7)+IF(F12=0,0,H11))) -> 0
A13: Méca | C13: 6 | D13: CC | E13: 1 | G13: =IF(COUNT(F13:F17)=1,AVERAGE(F13:F17),(SUM(F13:F17)-MIN(F13:F17))/(COUNT(F13:F17)-1)) -> 0 | H13: 0.2 | I13: =IF(SUM(F13:F17,F18:G19)=0,0,(G13*H13+F18*H18+F19*H19)/(IF(G13=0,0,H13)+IF(F18=0,0,H18)+IF(F19=0,0,H19))) -> 0
E14: 2
E15: 3
E16: 4
E17: 5
D18: Examen | E18: 1 | H18: 0.4
E19: 2 | H19: 0.4
A20: Physique-chimie | B20: Physique | C20: 6 | D20: Khôlle | H20: 0.1 | I20: =IF(SUM(F20:G23)=0,0,(F20*H20+F21*H21+F22*H22+F23*H23)/(IF(F20=0,0,H20)+IF(F21=0,0,H21)+IF(F22=0,0,H22)+IF(F23=0,0,H23))) -> 0 | J20: =IF(SUM(F20:G27)=0,0,(I20+I24)/(IF(I20=0,0,1)+IF(I24=0,0,1))) -> 0
D21: DS | E21: 1 | H21: 0.2
E22: 2 | H22: 0.3
D23: Examen | H23: 0.4
B24: Chimie | D24: Khôlle | H24: 0.1 | I24: =IF(SUM(F24:G27)=0,0,(F24*H24+F25*H25+F26*H26+F27*H27)/(IF(F24=0,0,H24)+IF(F25=0,0,H25)+IF(F26=0,0,H26)+IF(F27=0,0,H27))) -> 0
D25: DS | E25: 1 | H25: 0.2
E26: 2 | H26: 0.3
D27: Examen | H27: 0.4
A28: Transversales | B28: Anglais | C28: 2 | D28: Moyenne | H28: 1 | I28: =F28 -> 0 | J28: =IF(SUM(F28:G31)=0,0,(I28+I29)/(IF(I28=0,0,1)+IF(I29=0,0,1))) -> 0
B29: Français | D29: Texte | H29: 0.4 | I29: =IF(SUM(F29:G31)=0,0,(F29*H29+F30*H30+F31*H31)/(IF(F29=0,0,H29)+IF(F30=0,0,H30)+IF(F31=0,0,H31))) -> 0
D30: Bibiographie | H30: 0.2
D31: Oral | H31: 0.4
B32: Pix | C32: 1 | D32: Compétences | E32: 1 | H32: 0.2 | I32: =IF(SUM(F32:G36)=0,0,AVERAGE(F32:G36)) -> 0
E33: 2 | H33: 0.2
E34: 3 | H34: 0.2
E35: 4 | H35: 0.2
E36: 5 | H36: 0.2
B37: PPP2 | C37: 2 | D37: Moyenne | H37: 1 | I37: =F37 -> 0
B38: Sport | C38: 1 | D38: Moyenne | H38: 1 | I38: =F38 -> 0
H39: SCIENCES | I39: =IF(SUM(I2:J27)=0,0,(I2*C2+I13*C13+J20*C20)/(IF(I2=0,0,C2)+IF(I13=0,0,C13)+IF(J20=0,0,C20))) -> 0
H40: TR | I40: =IF(SUM(I28:J38)=0,"- - -",IF(AND(OR(J28=0,J28>=10),OR(I32=0,I32>=10),OR(I37=0,I37>=10),OR(I38=0,I38>=10)),"VAL","NVAL")) -> - - -
...

Sheet Semestre 3
A1: UE | C1: Crédits | D1: Evaluations | F1: Notes | H1: Coefficients | J1: Moyenne
A2: Maths | C2: 12 | D2: Khôlles | E2: 1 | G2: =IF(COUNT(F2:F6)=1,AVERAGE(F2:F6),(SUM(F2:F6)-MIN(F2:F6))/(COUNT(F2:F6)-1)) -> 0 | H2: 0.3 | J2: =IF(SUM(F2:G12)=0,0,(G2*H2+G7*H7+G11*H11)/(IF(G2=0,0,H2)+IF(G7=0,0,H7)+IF(G11=0,0,H11))) -> 0
E3: 2
E4: 3
E5: 4
E6: 5
D7: DS | E7: 1 | G7: =IF(COUNT(F7:F10)=0,0,AVERAGE(F7:F10)) -> 0 | H7: 0.3
E8: 2
E9: 3
E10: 4
A11: Algèbre | D11: Examen | G11: =IF(COUNT(F11:F12)=0,0,AVERAGE(F11:F12)) -> 0 | H11: 0.4 | J11: =IF(SUM(F2:G10)+F11=0,0,(G2*H2+G7*H7+F11*H11)/(IF(G2=0,0,H2)+IF(G7=0,0,H7)+IF(F11=0,0,H11))) -> 0
A12: Analyse | J12: =IF(SUM(F2:G10)+F12=0,0,(G2*H2+G7*H7+F12*H11)/(IF(G2=0,0,H2)+IF(G7=0,0,H7)+IF(F12=0,0,H11))) -> 0
A13: Méca | C13: 6 | D13: DS | E13: DS 1 | G13: =IF(SUM(F13:F15)=0,0,(F13*H13+F14*H14+F15*H15)/(IF(F13=0,0,H13)+IF(F14=0,0,H14)+IF(F15=0,0,H15))) -> 0 | H13: =IF(SUM(F13:F14)=0,0.25,IF(AVERAGE(F13:F14)>=F15,0.25,0)) -> 0.25 | I13: 0.5 | J13: =IF(SUM(F13:G16)=0,0,(G13*I13+F16*H16)/(IF(G13=0,0,I13)+IF(F16=0,0,H16))) -> 0
E14: DS 2 | H14: =IF(SUM(F13:F14)=0,0.25,IF(AVERAGE(F13:F14)>=F15,0.25,0)) -> 0.25
E15: Partiel | H15: =IF(SUM(F13:F14)=0,0.5,IF(AVERAGE(F13:F14)>=F15,0.5,1)) -> 0.5
D16: Examen | H16: 0.5
A17: Electromag | C17: 6 | D17: TP | E17: 1 | G17: =IF(SUM(F17:F19)=0,0,AVERAGE(F17:F19)) -> 0 | H17: 0.07 | J17: =IF(SUM(F17:G22)=0,0,(G17*H17+F20*H20+F21*H21+F22*H22)/(IF(G17=0,0,H17)+IF(F20=0,0,H20)+IF(F21=0,0,H21)+IF(F22=0,0,H22))) -> 0
E18: 2
E19: 3
D20: TP noté | H20: 0.18
D21: DS | H21: 0.35
D22: Examen | H22: 0.4
A23: Transversales | B23: Anglais | C23: 3 | D23: Moyenne | H23: 1 | J23: =F23 -> 0 | K23: =IF(SUM(F23:G25)=0,0,(J23+J24)/(IF(J23=0,0,1)+IF(J24=0,0,1))) -> 0
B24: Français | D24: Module | E24: 1 | H24: 1 | J24: =IF(COUNT(F24:G25)=0,0,AVERAGE(F24:G25)) -> 0
E25: 2
B26: Sport | C26: 1 | D26: Moyenne | H26: 1 | J26: =F26 -> 0
B27: POTE | C27: 2 | D27: Moyenne | H27: 1 | J27: =F27 -> 0 | K27: =IF(SUM(F27:G28)=0,0,(J27+J28)/(IF(J27=0,0,1)+IF(J28=0,0,1))) -> 0
B28: Stage | D28: Moyenne | H28: 1 | J28: =F28 -> 0
H29: SCIENCES | J29: =IF(SUM(J2:K22)=0,0,(J2*C2+J13*C13+J17*C17)/(IF(J2=0,0,C2)+IF(J13=0,0,C13)+IF(J17=0,0,C17))) -> 0
H30: TR | J30: =IF(SUM(J23:K28)=0,"- - -",IF(AND(OR(K23=0,K23>=10),OR(J26=0,J26>=10),OR(K27=0,K27>=10)),"VAL","NVAL")) -> - - -
H31: TOTAL | J31: =IF(SUM(J2:K28)=0,0,(J2*C2+J13*C13+J17*C17+K23*C23+J26*C26+K27*C27)/(IF(J2=0,0,C2)+IF(J13=0,0,C13)+IF(J17=0,0,C17)+IF(K23=0,0,C23)+IF(J26=0,0,C26)+IF(K27=0,0,C27))) -> 0
H32: =IF(J29=0,"- - -",IF(AND(J29>=10,NOT(J30="NVAL")),"Semestre validé","Semestre échoué")) -> - - -

Sheet Semestre 4
A1: UE | C1: Crédits | D1: Evaluations | F1: Notes | H1: Coefficients | J1: Moyenne
A2: Maths | C2: 12 | D2: Khôlles | E2: 1 | G2: =IF(COUNT(F2:F6)=1,AVERAGE(F2:F6),(SUM(F2:F6)-MIN(F2:F6))/(COUNT(F2:F6)-1)) -> 0 | H2: 0.3 | J2: =IF(SUM(F2:G12)=0,0,(G2*H2+G7*H7+G11*H11)/(IF(G2=0,0,H2)+IF(G7=0,0,H7)+IF(G11=0,0,H11))) -> 0
E3: 2
E4: 3
E5: 4
E6: 5
D7: DS | E7: 1 | G7: =IF(COUNT(F7:F10)=0,0,AVERAGE(F7:F10)) -> 0 | H7: 0.3
E8: 2
E9: 3
E10: 4
A11: Algèbre | D11: Examen | G11: =IF(COUNT(F11:F12)=0,0,AVERAGE(F11:F12)) -> 0 | H11: 0.4 | J11: =IF(SUM(F2:G10)+F11=0,0,(G2*H2+G7*H7+F11*H11)/(IF(G2=0,0,H2)+IF(G7=0,0,H7)+IF(F11=0,0,H11))) -> 0
A12: Analyse | J12: =IF(SUM(F2:G10)+F12=0,0,(G2*H2+G7*H7+F12*H11)/(IF(G2=0,0,H2)+IF(G7=0,0,H7)+IF(F12=0,0,H11))) -> 0
A13: Thermo | C13: 6 | D13: TP | E13: 1 | G13: =IF(SUM(F13:F16)=0,0,(F13*H13+F14*H14+F15*H15+F16*H16)/(IF(F13=0,0,H13)+IF(F14=0,0,H14)+IF(F15=0,0,H15)+IF(F16=0,0,H16))) -> 0 | H13: =1/6 -> 0.16666667 | I13: =1/3 -> 0.33333333 | J13: =IF(SUM(F13:G17)=0,0,(G13*I13+F17*H17)/(IF(G13=0,0,I13)+IF(F17=0,0,H17))) -> 0
E14: 2 | H14: =1/6 -> 0.16666667
E15: 3 | H15: =1/6 -> 0.16666667
E16: final | H16: 0.5
D17: Examen | H17: =2/3 -> 0.66666667
A18: Optique | C18: 6 | D18: TP | E18: 1 | G18: =IF(SUM(F18:F22)=0,0,AVERAGE(F18:F22)) -> 0 | H18: 0.1 | I18: 0.3 | J18: =IF(SUM(F18:F24)=0,0,(G18*I18+G23*I23)/(IF(G18=0,0,I18)+IF(G23=0,0,I23))) -> 0
E19: 2 | H19: 0.1
E20: 3 | H20: 0.1
E21: 4 | H21: 0.1
E22: final | H22: 0.6
D23: DS | G23: =IF(SUM(F23:F24)=0,0,(F23*H23+F24*H24)/(IF(F23=0,0,H23)+IF(F24=0,0,H24))) -> 0 | H23: =IF(F23>=F24,0.5,0) -> 0.5 | I23: 0.7
D24: Examen | H24: 0.5
A25: Transversales | B25: Anglais | C25: 2 | D25: Moyenne | H25: 1 | J25: =F25 -> 0 | K25: =IF(SUM(F25:G28)=0,0,(J25+J26)/(IF(J25=0,0,1)+IF(J26=0,0,1))) -> 0
B26: Français | D26: Bibliographie | H26: 1 | J26: =IF(COUNT(F26:G28)=0,0,AVERAGE(F26:G28)) -> 0
D27: Texte
D28: Oral
B29: Sport | C29: 1 | D29: Moyenne | H29: 1 | J29: =F29 -> 0
B30: Projet | C30: 2 | D30: Moyenne | H30: 1 | J30: =F30 -> 0
B31: Renforcement | C31: 1 | D31: Moyenne | H31: 1 | J31: =F31 -> 0
H32: SCIENCES | J32: =IF(SUM(J2:K24)=0,0,(J2*C2+J13*C13+J18*C18)/(IF(J2=0,0,C2)+IF(J13=0,0,C13)+IF(J18=0,0,C18))) -> 0
H33: TR | J33: =IF(SUM(J25:K31)=0,"- - -",IF(AND(OR(K25=0,K25>=10),OR(J29=0,J29>=10),OR(J30=0,J30>=10),OR(J31=0,J31>=10)),"VAL","NVAL")) -> - - -
H34: TOTAL | J34: =IF(SUM(J2:K31)=0,0,(J2*C2+J13*C13+J18*C18+K25*C25+J29*C29+J30*C30+J31*C31)/(IF(J2=0,0,C2)+IF(J13=0,0,C13)+IF(J18=0,0,C18)+IF(K25=0,0,C25)+IF(J29=0,0,C29)+IF(J30=0,0,C30)+IF(J31=0,0,C31))) -> 0
H35: =IF(J32=0,"- - -",IF(AND(J32>=10,NOT(J33="NVAL")),"Semestre validé","Semestre échoué")) -> - - -
