Workbook

Sheet HOME
A1: Saint-Tableur Polytech Lyon Info
A2: ! Ce tableur et ses informations ne sont pas officiels !
A3: Tableur original créé par Julien de la promo FISE 2024-2027.
A5: Il y a un onglet par semestre pour les FISE et pour les FISA.
A6: Veuillez rentrer des valeurs seulement dans les cases grises.
A7: Les résultats par semestres sont résumés dans le tableau ci-dessous.
A8: Sont seulement pris en compte dans le tableur les semestres généralistes, libre à vous de l’adapter en fonction de votre trajectoire.
A10: FISE
A11: Semestre | B11: S5 | C11: S6 | D11: S7 | E11: S8 | F11: S9 | G11: S10
A12: Note | B12: =IF(COUNTA(B13)=0,S5_FISE!E38,B13) -> 0 | C12: =IF(COUNTA(C13)=0,S6_FISE!E40,C13) -> 0 | D12: =IF(COUNTA(D13)=0,S7_FISE!E5,D13) -> 0 | E12: =IF(COUNTA(E13)=0,S8_FISE!E43,E13) -> 0 | F12: =IF(COUNTA(F13)=0,S9_FISE!E26,F13) -> 0 | G12: =IF(COUNTA(G13)=0,S10_FISE!E3,G13) -> 0
A13: Forcer la note
A15: FISA
A16: Semestre | B16: S5 | C16: S6 | D16: S7 | E16: S8 | F16: S9 | G16: S10
A17: Note | B17: =IF(COUNTA(B18)=0,S5_FISA!E17,B18) -> 0 | C17: =IF(COUNTA(C18)=0,S6_FISA!E16,C18) -> 0
A18: Forcer la note
A20: Quitus
A21: Quitus | B21: Charte HVSS | C21: Expérience professionnelle | D21: TOEIC | E21: Mobilité internationale
A22: Validation | B22: =IF(B23,"Valide","Valide pas") -> Valide pas | C22: =IF(C23,"Valide","Valide pas") -> Valide pas | D22: =IF(D23,"Valide","Valide pas") -> Valide pas | E22: =IF(E23,"Valide","Valide pas") -> Valide pas
A23: Valider | B23: 0 | C23: 0 | D23: 0 | E23: 0

Sheet S5_FISE
A1: UE | B1: Matières | C1: Crédits | E1: Notes & coefficients | H1: Moyennes
A2: Introduction Mathématiques et Informatique | B2: Fondements Maths et Informatique (Début d’année) | C2: 8 | D2: 4 | E2: Fondements Maths | F2: =1/6 -> 0.16666667 | H2: =G2*F2+G3*F3+G4*F4+G5*F5+G6*F6+G7*F7 -> 0 | I2: =(H2*D2+H8*D8+H10*D10)/C2 -> 0
E3: Fondements Algorithmique | F3: =1/6 -> 0.16666667
E4: APO - Initiation | F4: =1/6 -> 0.16666667
E5: Web - Initiation | F5: =1/6 -> 0.16666667
E6: Python - Initiation | F6: =1/6 -> 0.16666667
E7: Projet Tutoré (En décembre) | F7: =1/6 -> 0.16666667
B8: Maths pour l’Info | D8: 1 | E8: QCM3 | F8: 0.1 | H8: =G8*F8+G9*F9 -> 0
E9: CC Final | F9: 0.9
B10: Probabilités et Statistique | D10: 3 | E10: Moyenne QCMs | F10: 0.5 | H10: =G10*F10+G11*F11 -> 0
E11: CC Final | F11: 0.5
A12: Algorithmique - Complexité - Programmation Objet | B12: Algorithmique Programmation Objet | C12: 5 | D12: 4 | E12: Moyenne QCMs | F12: 0.25 | H12: =G12*F12+G13*F13+G14*F14+G15*F15 -> 0 | I12: =(H12*D12+H16*D16)/C12 -> 0
E13: Projet | F13: 0.25
E14: CC TD | F14: 0.25
E15: CC Final | F15: 0.25
B16: Algorithmique et Complexité 1 | D16: 1 | E16: TP Noté | F16: 0.4 | H16: =G16*F16+G17*F17 -> 0
E17: CC Final | F17: 0.6
A18: Informatique de gestion - Initiation | B18: ISI1 Web | C18: 5 | D18: 1 | E18: Projet | F18: 0.6 | H18: =G18*F18+G19*F19 -> 0 | I18: =(H18*D18+H20*D20+H22*D22)/C18 -> 0
E19: QCM | F19: 0.4
B20: Ingénierie des Systèmes d’Informations 1 | D20: 2 | E20: Projet | F20: 0.5 | H20: =G20*F20+G21*F21 -> 0
E21: CC Final | F21: 0.5
B22: Base de Données 1 | D22: 2 | E22: Moyenne TPs | F22: 0.4 | H22: =G22*F22+G23*F23+G24*F24 -> 0
E23: CC1 | F23: 0.3
E24: CC2 | F24: 0.3
A25: Signal et Hardware | B25: Théorie des Langages et Compilation | C25: 4 | D25: 2 | E25: Projet | F25: 0.4 | H25: =F25*G25+F26*G26 -> 0 | I25: =(H25*D25+H27*D27)/C25 -> 0
E26: CC Final | F26: 0.6
B27: Structure des Calculateurs | D27: 2 | E27: Projet | F27: 0.4 | H27: =F27*G27+F28*G28 -> 0
E28: CC Final | F28: 0.6
A29: Langues | B29: Anglais | C29: 3 | D29: 2 | E29: Moyenne | F29: 1 | H29: =G29*F29 -> 0 | I29: =(H29*D29+H30*D30)/C29 -> 0
B30: Anglais renforcé -OU- LV2 | D30: 1 | E30: Moyenne | F30: 1 | H30: =G30*F30 -> 0
A31: Ouverture aux entreprises | B31: Gestion / Jeu d’entreprise | C31: 4 | D31: 2 | E31: Gestion Entreprise | F31: 0.75 | H31: =G31*F31+G32*F32 -> 0 | I31: =(H31*D31+H33*D33+H35*D35)/C31 -> 0
E32: Oral Final | F32: 0.25
B33: Entreprise et Vie Économique | D33: 1.5 | E33: Moyenne TDs | F33: 0.5 | H33: =G33*F33+G34*F34 -> 0
E34: Dossier Kalypso | F34: 0.5
B35: Sport | D35: 0.5 | E35: Moyenne | F35: 1 | H35: =G35*F35 -> 0
A36: PPP | B36: Développement de sa Trajectoire | C36: 1 | D36: 1 | E36: Poster | F36: 0.5 | H36: =G36*F36+G37*F37 -> 0 | I36: =(H36*D36)/C36 -> 0
E37: Portrait | F37: 0.5
A38: Total | C38: =SUM(C2:C36) -> 30 | E38: =(I2*C2+I12*C12+I18*C18+I25*C25+I29*C29+I31*C31+I36*C36)/C38 -> 0 | H38: =IF(OR(I2<10,I12<10,I18<10,I25<10,I29<10,I31<10,I36<10),"Valide pas","Valide") -> Valide pas

Sheet S6_FISE
A1: UE | B1: Matières | C1: Crédits | E1: Notes & coefficients | H1: Moyennes
A2: Mathématiques discrètes et Statistiques | B2: Mathématiques discrètes | C2: 7 | D2: 2 | E2: CC Bonus | F2: 0.5 | H2: =G2*F2+G3*F3 -> 0 | I2: =(H2*D2+H4*D4+H6*D6)/C2 -> 0
E3: CC Final | F3: 0.5
B4: Graphes & Applications | D4: 2 | E4: CC1 | F4: 0.5 | H4: =G4*F4+G5*F5 -> 0
E5: CC2 | F5: 0.5
B6: Méthodes Statistiques pour l’Ingénieur | D6: 3 | E6: TP Noté | F6: 0.33333333 | H6: =G6*F6+G7*F7 -> 0
E7: CC Final | F7: 0.66666667
A8: Algorithmique - Programmation | B8: Algorithmique et Complexité 2 | C8: 3 | D8: 2 | E8: TP Noté | F8: 0.4 | H8: =G8*F8+G9*F9 -> 0 | I8: =(H8*D8+H10*D10)/C8 -> 0
E9: CC Final | F9: 0.6
B10: Projet Informatique Encadré | D10: 1 | E10: Projet | F10: 1 | H10: =G10*F10 -> 0
A11: Informatique de gestion - Niveau 2 | B11: Base de Données 2 | C11: 5 | D11: 2 | E11: CC BDR | F11: 0.4 | H11: =G11*F11+G12*F12+G13*F13+G14*F14 -> 0 | I11: =(H11*D11+H15*D15+H18*D18+H21*D21)/C11 -> 0
E12: TP BDR | F12: 0.2
E13: TP XML | F13: 0.2
E14: TP ORM | F14: 0.2
B15: Ingénierie des Systèmes d’Informations 2 | D15: 1 | E15: Assiduité | F15: 0.1 | H15: =G15*F15+G16*F16+G17*F17 -> 0
E16: Projet | F16: 0.3
E17: TP Colle | F17: 0.6
B18: Modélisation des Données | D18: 1 | E18: Assiduité | F18: 0.2 | H18: =G18*F18+G19*F19+G20*F20 -> 0
E19: CC1 | F19: 0.3
E20: CC2 | F20: 0.5
B21: Méthodes Agiles | D21: 1 | E21: TP GIT | F21: 0.2 | H21: =G21*F21+G22*F22+G23*F23 -> 0
E22: Projet Agile | F22: 0.4
E23: CC Agile | F23: 0.4
A24: Réseaux d’ordinateurs et Systèmes d’Exploitation | B24: Réseaux d’ordinateurs | C24: 6 | D24: 3 | E24: QCM | F24: 0.2 | H24: =F24*G24+F25*G25+F26*G26 -> 0 | I24: =(H24*D24+H27*D27)/C24 -> 0
E25: Moyenne TPs | F25: 0.4
E26: CC Final | F26: 0.4
B27: Systèmes d’Exploitation | D27: 3 | E27: TPs Windows | F27: =1/3 -> 0.33333333 | H27: =F27*G27+F28*G28+F29*G29 -> 0
E28: TPs Linux | F28: =1/3 -> 0.33333333
E29: CC Final | F29: =1/3 -> 0.33333333
A30: DDRS | B30: Enjeux Sociétaux et Environnementaux | C30: 1 | D30: 1 | E30: Polytest | F30: 0.5 | H30: =G30*F30+G31*F31 -> 0 | I30: =(H30*D30)/C30 -> 0
E31: Rapport TDs | F31: 0.5
A32: Langues | B32: Anglais | C32: 3 | D32: 2 | E32: Moyenne | F32: 1 | H32: =G32*F32 -> 0 | I32: =(H32*D32+H33*D33)/C32 -> 0
B33: Anglais renforcé -OU- LV2 | D33: 1 | E33: Moyenne | F33: 1 | H33: =G33*F33 -> 0
A34: Ouverture aux entreprises | B34: Communication interpersonnelle | C34: 4 | D34: 1 | E34: Pitch Oral | F34: 0.5 | H34: =G34*F34+G35*F35 -> 0 | I34: =(H34*D34+H36*D36+H38*D38)/C34 -> 0
E35: Pitch Ecrit | F35: 0.5
B36: Projet de Création d’Entreprise | D36: 2.5 | E36: Business Plan | F36: 0.5 | H36: =G36*F36+G37*F37 -> 0
E37: Oral Final | F37: 0.5
B38: Sport | D38: 0.5 | E38: Moyenne | F38: 1 | H38: =G38*F38 -> 0
A39: PPP | B39: Approche compétence et Suivi de stage | C39: 1 | D39: 1 | E39: QCM | F39: 1 | H39: =G39*F39 -> 0 | I39: =(H39*D39)/C39 -> 0
A40: Total | C40: =SUM(C2:C39) -> 30 | E40: =(I2*C2+I8*C8+I11*C11+I24*C24+I30*C30+I32*C32+I34*C34+I39*C39)/C40 -> 0 | H40: =IF(OR(I2<10,I8<10,I11<10,I24<10,I30<10,I32<10,I34<10,I39<10),"Valide pas","Valide") -> Valide pas

Sheet S7_FISE
A1: UE | B1: Matières | C1: Crédits | E1: Notes & coefficients | H1: Moyennes
A2: Stage | B2: Stage | C2: 30 | D2: 30 | E2: Soutenance | F2: =1/3 -> 0.33333333 | H2: =F2*G2+F3*G3+G4*F4 -> 0 | I2: =(H2*D2)/C2 -> 0
E3: Mémoire | F3: =1/3 -> 0.33333333
E4: Entreprise | F4: =1/3 -> 0.33333333
A5: Total | C5: =SUM(C2:C2) -> 30 | E5: =(I2*C2)/C5 -> 0 | H5: =IF(OR(I2<10),"Valide pas","Valide") -> Valide pas

Sheet S8_FISE
A1: UE | B1: Matières | C1: Crédits | E1: Notes & coefficients | H1: Moyennes
A2: Connaissances théoriques | B2: Optimisation discrète | C2: 10 | D2: 2 | E2: CC1 | F2: =30/225 -> 0.13333333 | H2: =G2*F2+G3*F3+G4*F4+G5*F5 -> 0 | I2: =(H2*D2+H6*D6+H10*D10+H13*D13)/C2 -> 0
E3: CC2 | F3: =70/225 -> 0.31111111
E4: CC3 | F4: =75/225 -> 0.33333333
E5: Projet | F5: =50/225 -> 0.22222222
B6: Intelligence Artificielle | D6: 3 | E6: Moyenne TPs | F6: 0.1 | H6: =G6*F6+G7*F7+G8*F8+G9*F9 -> 0
E7: CC1 | F7: 0.2
E8: CC2 | F8: 0.3
E9: CC Final | F9: 0.4
B10: ARSIR | D10: 3 | E10: QCM | F10: 0.2 | H10: =G10*F10+G11*F11+G12*F12 -> 0
E11: Moyenne TPs | F11: 0.4
E12: CC Final | F12: 0.4
B13: Cryptographie | D13: 2 | E13: QCM | F13: 0.5 | H13: =G13*F13+G14*F14 -> 0
E14: CC Final | F14: 0.5
A15: Aide à la décision | B15: Analyse des Données Multidimensionnelles | C15: 4 | D15: 2 | E15: TP1 | F15: 0.2 | H15: =G15*F15+G16*F16+G17*F17+G18*F18 -> 0 | I15: =(H15*D15+H19*D19)/C15 -> 0
E16: TP2 | F16: 0.2
E17: TP3 | F17: 0.2
E18: CC Final | F18: 0.4
B19: Systèmes d'Information d'Aide à la Décision | D19: 2 | E19: Moyenne TPs | F19: 0.3 | H19: =G19*F19+G20*F20+G21*F21 -> 0
E20: Projet | F20: 0.3
E21: CC Final | F21: 0.4
A22: Ingénierie des Systèmes d’Informations & Informatique répartie | B22: Ingénierie des Systèmes d’Informations 3 | C22: 5 | D22: 2 | E22: Moyenne TPs | F22: 0.1 | H22: =G22*F22+G23*F23+G24*F24+G25*F25 -> 0 | I22: =(H22*D22+H26*D26+H28*D28)/C22 -> 0
E23: CC1 | F23: 0.2
E24: CC2 | F24: 0.3
E25: CC Final | F25: 0.4
B26: Informatique répartie | D26: 2 | E26: Moyenne QCMs | F26: 0.6 | H26: =G26*F26+G27*F27 -> 0
E27: Projet | F27: 0.4
B28: WEB Services | D28: 1 | E28: QCM | F28: =1/3 -> 0.33333333 | H28: =G28*F28+G29*F29 -> 0
E29: Projet | F29: =2/3 -> 0.66666667
A30: Informatique dans l'industrie & Lean | B30: Industrie 4.0/Enjeux sociétaux et environnementaux/Green IT | C30: 3 | D30: 2 | E30: TP Green IT | F30: 0.3 | H30: =F30*G30+G31*F31+G32*F32 -> 0 | I30: =(H30*D30+H33*D33)/C30 -> 0
E31: TP Industrie 4.0 | F31: 0.3
E32: CC Final | F32: 0.4
B33: Lean management | D33: 1 | E33: Participation | F33: 1 | H33: =G33*F33 -> 0
A34: Langues | B34: Anglais | C34: 3 | D34: 2 | E34: Moyenne | F34: 1 | H34: =G34*F34 -> 0 | I34: =(H34*D34+H35*D35)/C34 -> 0
B35: Anglais renforcé -OU- LV2 | D35: 1 | E35: Moyenne | F35: 1 | H35: =G35*F35 -> 0
A36: Ouverture aux entreprises | B36: Management d'équipe | C36: 4 | D36: 1 | E36: Présentation | F36: 1 | H36: =G36*F36 -> 0 | I36: =(H36*D36+H37*D37+H38*D38+H40*D40)/C36 -> 0
B37: Développement de la Performance | D37: 1.5 | E37: Rapport | F37: 1 | H37: =G37*F37 -> 0
B38: Droit de la Propriété Intellectuelle | D38: 1 | E38: Moyenne QCMs | F38: 0.5 | H38: =G38*F38+G39*F39 -> 0
E39: Rapport | F39: 0.5
B40: Sport | D40: 0.5 | E40: Moyenne | F40: 1 | H40: =G40*F40 -> 0
...

Sheet S9_FISE
A1: UE | B1: Matières | C1: Crédits | E1: Notes & coefficients | H1: Moyennes
A2: Systèmes Informatiques | B2: Administration systèmes et Cloud | C2: 6 | D2: 1 | E2: Moyenne | F2: 1 | H2: =G2*F2 -> 0 | I2: =(H2*D2+H3*D3+H4*D4+H5*D5)/C2 -> 0
B3: Sécurité des Systèmes Informatiques | D3: 1 | E3: Moyenne | F3: 1 | H3: =G3*F3 -> 0
B4: Mécatronique, Informatique pour la production | D4: 2 | E4: Moyenne | F4: 1 | H4: =G4*F4 -> 0
B5: Signal et Télécommunications | D5: 2 | E5: Moyenne | F5: 1 | H5: =G5*F5 -> 0
A6: Nouvelles technologies | B6: Applications informatiques mobiles | C6: 4 | D6: 1 | E6: Moyenne | F6: 1 | H6: =G6*F6 -> 0 | I6: =(H6*D6+H7*D7+H8*D8+H9*D9)/C6 -> 0
B7: Internet des Objets | D7: 1 | E7: Moyenne | F7: 1 | H7: =G7*F7 -> 0
B8: Applications informatiques embarquées | D8: 1 | E8: Moyenne | F8: 1 | H8: =G8*F8 -> 0
B9: Vulgarisation industrielle | D9: 1 | E9: Moyenne | F9: 1 | H9: =G9*F9 -> 0
A10: Systèmes d'Information | B10: Intégration des Systèmes d'Information | C10: 2 | D10: 1 | E10: Moyenne | F10: 1 | H10: =G10*F10 -> 0 | I10: =(H10*D10+H11*D11)/C10 -> 0
B11: Gestion de Projet Informatique | D11: 1 | E11: Moyenne | F11: 1 | H11: =G11*F11 -> 0
A12: Ouverture à la Recherche | B12: Systèmes Multi-agents | C12: 6 | D12: 2 | E12: Moyenne | F12: 1 | H12: =G12*F12 -> 0 | I12: =(H12*D12+H13*D13+H14*D14)/C12 -> 0
B13: Big Data | D13: 2 | E13: Moyenne | F13: 1 | H13: =G13*F13 -> 0
B14: Apprentissage profond | D14: 2 | E14: Moyenne | F14: 1 | H14: =G14*F14 -> 0
A15: Professionalisation Informatique | B15: Projet Tutoré Business Intelligence | C15: 4 | D15: 2 | E15: Moyenne | F15: 1 | H15: =G15*F15 -> 0 | I15: =(H15*D15+H16*D16+H17*D17)/C15 -> 0
B16: Projet Turoré Conception Developpement | D16: 1 | E16: Moyenne | F16: 1 | H16: =G16*F16 -> 0
B17: Qualité & Tests logiciels | D17: 1 | E17: Moyenne | F17: 1 | H17: =G17*F17 -> 0
A18: Langues | B18: Anglais | C18: 3 | D18: 2 | E18: Moyenne | F18: 1 | H18: =G18*F18 -> 0 | I18: =(H18*D18+H19*D19)/C18 -> 0
B19: Anglais renforcé -OU- LV2 | D19: 1 | E19: Moyenne | F19: 1 | H19: =G19*F19 -> 0
A20: Ouverture aux entreprises | B20: Ressources Humaines | C20: 4 | D20: 0.5 | E20: Moyenne | F20: 1 | H20: =G20*F20 -> 0 | I20: =(H20*D20+H21*D21+H22*D22+H23*D23+H24*D24)/C20 -> 0
B21: Web Marketing | D21: 1 | E21: Moyenne | F21: 1 | H21: =G21*F21 -> 0
B22: User Center Design | D22: 1 | E22: Moyenne | F22: 1 | H22: =G22*F22 -> 0
B23: Analyse Financière | D23: 1 | E23: Moyenne | F23: 1 | H23: =G23*F23 -> 0
B24: Sport | D24: 0.5 | E24: Moyenne | F24: 1 | H24: =G24*F24 -> 0
A25: PPP | B25: Préparation au mémoire et Insertion | C25: 1 | D25: 1 | E25: Moyenne | F25: 1 | H25: =G25*F25 -> 0 | I25: =(H25*D25)/C25 -> 0
A26: Total | C26: =SUM(C2:C25) -> 30 | E26: =(I2*C2+I6*C6+I10*C10+I12*C12+I15*C15+I18*C18+I20*C20+I25*C25)/C26 -> 0 | H26: =IF(OR(I2<10,I6<10,I10<10,I12<10,I15<10,I18<10,I20<10,I25<10),"Valide pas","Valide") -> Valide pas

Sheet S10_FISE
A1: UE | B1: Matières | C1: Crédits | E1: Notes & coefficients | H1: Moyennes
A2: Stage | B2: Stage | C2: 30 | D2: 30 | E2: Stage | F2: 1 | H2: =F2*G2 -> 0 | I2: =(H2*D2)/C2 -> 0
A3: Total | C3: =SUM(C2:C2) -> 30 | E3: =(I2*C2)/C3 -> 0 | H3: =IF(OR(I2<10),"Valide pas","Valide") -> Valide pas

Sheet S5_FISA
A1: UE | B1: Matières | C1: Crédits | E1: Notes & coefficients | H1: Moyennes
A2: Mathématiques et Probabilités Statistiques | B2: Fondements Maths et Informatique (Début d’année) | C2: 8 | D2: 4 | E2: Fondements Maths | F2: 0.2 | H2: =G2*F2+G3*F3+G4*F4+G5*F5+G6*F6 -> 0 | I2: =(H2*D2+H7*D7+H8*D8)/C2 -> 0
E3: Fondements Algorithmique | F3: 0.2
E4: APO - Initiation | F4: 0.2
E5: Web - Initiation | F5: 0.2
E6: Python - Initiation | F6: 0.2
B7: Maths pour l’Info | D7: 2 | E7: Moyenne | F7: 1 | H7: =G7*F7 -> 0
B8: Probabilités et Statistique | D8: 2 | E8: Moyenne | F8: 1 | H8: =G8*F8 -> 0
A9: Spécialité Informatique | B9: Algorithmique Programmation Objet | C9: 6 | D9: 3 | E9: Moyenne | F9: 1 | H9: =G9*F9 -> 0 | I9: =(H9*D9+H10*D10)/C9 -> 0
B10: Systèmes d'Exploitations | D10: 3 | E10: Moyenne | F10: 1 | H10: =G10*F10 -> 0
A11: Informatique de gestion | B11: Base de Données | C11: 4 | D11: 2 | E11: Moyenne | F11: 1 | H11: =G11*F11 -> 0 | I11: =(H11*D11+H12*D12)/C11 -> 0
B12: Projet Tutoré | D12: 2 | E12: Moyenne | F12: 1 | H12: =G12*F12 -> 0
A13: Ouverture aux entreprises - Langues | B13: Gestion / Jeu d’entreprise | C13: 8 | D13: 3 | E13: Moyenne | F13: 1 | H13: =G13*F13 -> 0 | I13: =(H13*D13+H14*D14+H15*D15)/C13 -> 0
B14: Entreprise et Vie Économique | D14: 2 | E14: Moyenne | F14: 1 | H14: =G14*F14 -> 0
B15: Anglais | D15: 3 | E15: Moyenne | F15: 1 | H15: =G15*F15 -> 0
A16: Apprentissage | B16: Apprentissage | C16: 4 | D16: 4 | E16: Moyenne | F16: 1 | H16: =G16*F16 -> 0 | I16: =(H16*D16)/C16 -> 0
A17: Total | C17: =SUM(C2:C16) -> 30 | E17: =(I2*C2+I9*C9+I11*C11+I13*C13+I16*C16)/C17 -> 0 | H17: =IF(OR(I2<10,I9<10,I11<10,I13<10,I16<10),"Valide pas","Valide") -> Valide pas

Sheet S6_FISA
A1: UE | B1: Matières | C1: Crédits | E1: Notes & coefficients | H1: Moyennes
A2: Mathématiques | B2: Mathématiques discrètes | C2: 4 | D2: 2 | E2: Moyenne | F2: 1 | H2: =G2*F2 -> 0 | I2: =(H2*D2+H3*D3)/C2 -> 0
B3: Méthodes Statistiques pour l’Ingénieur | D3: 2 | E3: Moyenne | F3: 1 | H3: =G3*F3 -> 0
A4: Informatique de gestion | B4: Ingénierie des Systèmes d’Informations 1 et 2 | C4: 5 | D4: 2 | E4: Moyenne | F4: 1 | H4: =G4*F4 -> 0 | I4: =(H4*D4+H5*D5+H6*D6+H7*D7)/C4 -> 0
B5: Méthodes Agiles | D5: 1 | E5: Moyenne | F5: 1 | H5: =G5*F5 -> 0
B6: Modélisation des Données | D6: 1 | E6: Moyenne | F6: 1 | H6: =G6*F6 -> 0
B7: Projet Informatique Encadré | D7: 1 | E7: Moyenne | F7: 1 | H7: =G7*F7 -> 0
A8: Méthodes et outils pour l’Ingénieur informaticien | B8: Framework Javascript | C8: 3 | D8: 1 | E8: Moyenne | F8: 1 | H8: =F8*G8 -> 0 | I8: =(H8*D8+H9*D9)/C8 -> 0
B9: Réseaux et Systèmes de communication | D9: 2 | E9: Moyenne | F9: 1 | H9: =F9*G9 -> 0
A10: Ouverture aux entreprises - Langues | B10: Projet de Création d’Entreprise | C10: 8 | D10: 3 | E10: Moyenne | F10: 1 | H10: =G10*F10 -> 0 | I10: =(H10*D10+H11*D11+H12*D12+H13*D13)/C10 -> 0
B11: Développement personnel 1 | D11: 1 | E11: Moyenne | F11: 1 | H11: =G11*F11 -> 0
B12: Communication interpersonnelle | D12: 1 | E12: Moyenne | F12: 1 | H12: =G12*F12 -> 0
B13: Anglais | D13: 3 | E13: Moyenne | F13: 1 | H13: =G13*F13 -> 0
A14: DDRS | B14: Enjeux Sociétaux et Environnementaux | C14: 1 | D14: 1 | E14: Moyenne | F14: 1 | H14: =G14*F14 -> 0 | I14: =(H14*D14)/C14 -> 0
A15: Apprentissage | B15: Apprentissage | C15: 9 | D15: 9 | E15: Moyenne | F15: 1 | H15: =G15*F15 -> 0 | I15: =(H15*D15)/C15 -> 0
A16: Total | C16: =SUM(C2:C15) -> 30 | E16: =(I2*C2+I4*C4+I8*C8+I10*C10+I14*C14+I15*C15)/C16 -> 0 | H16: =IF(OR(I2<10,I4<10,I8<10,I10<10,I14<10,I15<10),"Valide pas","Valide") -> Valide pas
